2020-01-15 02:35:04,553 INFO: Microblog startup [in /home/phantsure/Documents/miblog/app/__init__.py:46]
2020-01-15 02:36:22,961 INFO: Microblog startup [in /home/phantsure/Documents/miblog/app/__init__.py:46]
2020-01-15 18:53:05,149 INFO: Microblog startup [in /home/phantsure/Documents/miblog/app/__init__.py:46]
2020-01-15 18:53:16,858 INFO: Microblog startup [in /home/phantsure/Documents/miblog/app/__init__.py:46]
2020-01-15 18:53:20,243 INFO: Microblog startup [in /home/phantsure/Documents/miblog/app/__init__.py:46]
2020-01-15 18:53:23,850 INFO: Microblog startup [in /home/phantsure/Documents/miblog/app/__init__.py:46]
2020-01-15 19:16:26,536 INFO: Microblog startup [in /home/phantsure/Documents/miblog/app/__init__.py:46]
2020-01-15 19:16:47,468 ERROR: Exception on /user/susan [GET] [in /home/phantsure/Documents/miblog/venv/lib/python3.6/site-packages/flask/app.py:1891]
Traceback (most recent call last):
  File "/home/phantsure/Documents/miblog/venv/lib/python3.6/site-packages/flask/app.py", line 2446, in wsgi_app
    response = self.full_dispatch_request()
  File "/home/phantsure/Documents/miblog/venv/lib/python3.6/site-packages/flask/app.py", line 1951, in full_dispatch_request
    rv = self.handle_user_exception(e)
  File "/home/phantsure/Documents/miblog/venv/lib/python3.6/site-packages/flask/app.py", line 1820, in handle_user_exception
    reraise(exc_type, exc_value, tb)
  File "/home/phantsure/Documents/miblog/venv/lib/python3.6/site-packages/flask/_compat.py", line 39, in reraise
    raise value
  File "/home/phantsure/Documents/miblog/venv/lib/python3.6/site-packages/flask/app.py", line 1949, in full_dispatch_request
    rv = self.dispatch_request()
  File "/home/phantsure/Documents/miblog/venv/lib/python3.6/site-packages/flask/app.py", line 1935, in dispatch_request
    return self.view_functions[rule.endpoint](**req.view_args)
  File "/home/phantsure/Documents/miblog/venv/lib/python3.6/site-packages/flask_login/utils.py", line 261, in decorated_view
    return func(*args, **kwargs)
  File "/home/phantsure/Documents/miblog/app/routes.py", line 69, in user
    return render_template('user.html', user=user, posts=posts)
  File "/home/phantsure/Documents/miblog/venv/lib/python3.6/site-packages/flask/templating.py", line 140, in render_template
    ctx.app,
  File "/home/phantsure/Documents/miblog/venv/lib/python3.6/site-packages/flask/templating.py", line 120, in _render
    rv = template.render(context)
  File "/home/phantsure/Documents/miblog/venv/lib/python3.6/site-packages/jinja2/asyncsupport.py", line 76, in render
    return original_render(self, *args, **kwargs)
  File "/home/phantsure/Documents/miblog/venv/lib/python3.6/site-packages/jinja2/environment.py", line 1008, in render
    return self.environment.handle_exception(exc_info, True)
  File "/home/phantsure/Documents/miblog/venv/lib/python3.6/site-packages/jinja2/environment.py", line 780, in handle_exception
    reraise(exc_type, exc_value, tb)
  File "/home/phantsure/Documents/miblog/venv/lib/python3.6/site-packages/jinja2/_compat.py", line 37, in reraise
    raise value.with_traceback(tb)
  File "/home/phantsure/Documents/miblog/app/templates/user.html", line 1, in top-level template code
    {% extends "base.html" %}
  File "/home/phantsure/Documents/miblog/app/templates/base.html", line 29, in top-level template code
    {% block content %}{% endblock %}
  File "/home/phantsure/Documents/miblog/app/templates/user.html", line 11, in block "content"
    <p>{{ user.followers.count() }} followers, {{ user.follwed.count() }} following.</p>
  File "/home/phantsure/Documents/miblog/venv/lib/python3.6/site-packages/jinja2/environment.py", line 430, in getattr
    return getattr(obj, attribute)
jinja2.exceptions.UndefinedError: 'app.models.User object' has no attribute 'follwed'
2020-01-15 19:16:58,222 ERROR: Exception on /user/susan [GET] [in /home/phantsure/Documents/miblog/venv/lib/python3.6/site-packages/flask/app.py:1891]
Traceback (most recent call last):
  File "/home/phantsure/Documents/miblog/venv/lib/python3.6/site-packages/flask/app.py", line 2446, in wsgi_app
    response = self.full_dispatch_request()
  File "/home/phantsure/Documents/miblog/venv/lib/python3.6/site-packages/flask/app.py", line 1951, in full_dispatch_request
    rv = self.handle_user_exception(e)
  File "/home/phantsure/Documents/miblog/venv/lib/python3.6/site-packages/flask/app.py", line 1820, in handle_user_exception
    reraise(exc_type, exc_value, tb)
  File "/home/phantsure/Documents/miblog/venv/lib/python3.6/site-packages/flask/_compat.py", line 39, in reraise
    raise value
  File "/home/phantsure/Documents/miblog/venv/lib/python3.6/site-packages/flask/app.py", line 1949, in full_dispatch_request
    rv = self.dispatch_request()
  File "/home/phantsure/Documents/miblog/venv/lib/python3.6/site-packages/flask/app.py", line 1935, in dispatch_request
    return self.view_functions[rule.endpoint](**req.view_args)
  File "/home/phantsure/Documents/miblog/venv/lib/python3.6/site-packages/flask_login/utils.py", line 261, in decorated_view
    return func(*args, **kwargs)
  File "/home/phantsure/Documents/miblog/app/routes.py", line 69, in user
    return render_template('user.html', user=user, posts=posts)
  File "/home/phantsure/Documents/miblog/venv/lib/python3.6/site-packages/flask/templating.py", line 140, in render_template
    ctx.app,
  File "/home/phantsure/Documents/miblog/venv/lib/python3.6/site-packages/flask/templating.py", line 120, in _render
    rv = template.render(context)
  File "/home/phantsure/Documents/miblog/venv/lib/python3.6/site-packages/jinja2/asyncsupport.py", line 76, in render
    return original_render(self, *args, **kwargs)
  File "/home/phantsure/Documents/miblog/venv/lib/python3.6/site-packages/jinja2/environment.py", line 1008, in render
    return self.environment.handle_exception(exc_info, True)
  File "/home/phantsure/Documents/miblog/venv/lib/python3.6/site-packages/jinja2/environment.py", line 780, in handle_exception
    reraise(exc_type, exc_value, tb)
  File "/home/phantsure/Documents/miblog/venv/lib/python3.6/site-packages/jinja2/_compat.py", line 37, in reraise
    raise value.with_traceback(tb)
  File "/home/phantsure/Documents/miblog/app/templates/user.html", line 1, in top-level template code
    {% extends "base.html" %}
  File "/home/phantsure/Documents/miblog/app/templates/base.html", line 29, in top-level template code
    {% block content %}{% endblock %}
  File "/home/phantsure/Documents/miblog/app/templates/user.html", line 11, in block "content"
    <p>{{ user.followers.count() }} followers, {{ user.follwed.count() }} following.</p>
  File "/home/phantsure/Documents/miblog/venv/lib/python3.6/site-packages/jinja2/environment.py", line 430, in getattr
    return getattr(obj, attribute)
jinja2.exceptions.UndefinedError: 'app.models.User object' has no attribute 'follwed'
2020-01-15 19:17:14,896 ERROR: Exception on /user/john [GET] [in /home/phantsure/Documents/miblog/venv/lib/python3.6/site-packages/flask/app.py:1891]
Traceback (most recent call last):
  File "/home/phantsure/Documents/miblog/venv/lib/python3.6/site-packages/flask/app.py", line 2446, in wsgi_app
    response = self.full_dispatch_request()
  File "/home/phantsure/Documents/miblog/venv/lib/python3.6/site-packages/flask/app.py", line 1951, in full_dispatch_request
    rv = self.handle_user_exception(e)
  File "/home/phantsure/Documents/miblog/venv/lib/python3.6/site-packages/flask/app.py", line 1820, in handle_user_exception
    reraise(exc_type, exc_value, tb)
  File "/home/phantsure/Documents/miblog/venv/lib/python3.6/site-packages/flask/_compat.py", line 39, in reraise
    raise value
  File "/home/phantsure/Documents/miblog/venv/lib/python3.6/site-packages/flask/app.py", line 1949, in full_dispatch_request
    rv = self.dispatch_request()
  File "/home/phantsure/Documents/miblog/venv/lib/python3.6/site-packages/flask/app.py", line 1935, in dispatch_request
    return self.view_functions[rule.endpoint](**req.view_args)
  File "/home/phantsure/Documents/miblog/venv/lib/python3.6/site-packages/flask_login/utils.py", line 261, in decorated_view
    return func(*args, **kwargs)
  File "/home/phantsure/Documents/miblog/app/routes.py", line 69, in user
    return render_template('user.html', user=user, posts=posts)
  File "/home/phantsure/Documents/miblog/venv/lib/python3.6/site-packages/flask/templating.py", line 140, in render_template
    ctx.app,
  File "/home/phantsure/Documents/miblog/venv/lib/python3.6/site-packages/flask/templating.py", line 120, in _render
    rv = template.render(context)
  File "/home/phantsure/Documents/miblog/venv/lib/python3.6/site-packages/jinja2/asyncsupport.py", line 76, in render
    return original_render(self, *args, **kwargs)
  File "/home/phantsure/Documents/miblog/venv/lib/python3.6/site-packages/jinja2/environment.py", line 1008, in render
    return self.environment.handle_exception(exc_info, True)
  File "/home/phantsure/Documents/miblog/venv/lib/python3.6/site-packages/jinja2/environment.py", line 780, in handle_exception
    reraise(exc_type, exc_value, tb)
  File "/home/phantsure/Documents/miblog/venv/lib/python3.6/site-packages/jinja2/_compat.py", line 37, in reraise
    raise value.with_traceback(tb)
  File "/home/phantsure/Documents/miblog/app/templates/user.html", line 1, in top-level template code
    {% extends "base.html" %}
  File "/home/phantsure/Documents/miblog/app/templates/base.html", line 29, in top-level template code
    {% block content %}{% endblock %}
  File "/home/phantsure/Documents/miblog/app/templates/user.html", line 11, in block "content"
    <p>{{ user.followers.count() }} followers, {{ user.follwed.count() }} following.</p>
  File "/home/phantsure/Documents/miblog/venv/lib/python3.6/site-packages/jinja2/environment.py", line 430, in getattr
    return getattr(obj, attribute)
jinja2.exceptions.UndefinedError: 'app.models.User object' has no attribute 'follwed'
